Workbook

Sheet 01目标路线
A1: PLEX｜长期完善与落地计划
A2: 总目标：把已有试用、微调和营收，沉淀为可教、可解释、可复核、可运营的 Python 数字教材产品。12个月执行，24个月条件式扩展。
A4: 启动日 | B4: 46282 | C4: 12个月截止 | D4: =EDATE(B4,12)-1 -> 46646 | E4: 任务数 | F4: =COUNTA('05执行证据'!A6:A37) -> 32 | G4: 任务完成率 | H4: =IFERROR(COUNTIF('05执行证据'!I6:I37,"已完成")/F4,0) -> 0
A5: A｜当前基础：按用户最新确认；旧文档只用于定位已有设计
A6: 项目 | B6: 当前值 / 状态 | C6: 口径 | D6: 下一步补齐 | E6: 主责角色 | F6: 时间 | G6: 依据 | H6: 判断边界
A7: 真实测试班级 | B7: 4 | C7: 已完成4个班测试 | D7: 班级、课程、时间与教师证明 | E7: 教研负责人 | F7: M1 | G7: 用户2026-09-17确认 | H7: 不把4个班当150个独立实验单元
A8: 真实测试学生 | B8: 150 | C8: 约150人；待按匿名ID去重 | D8: 参与、有效前后测、退出人数分开列 | E8: 科研负责人 | F8: M1 | G8: 用户2026-09-17确认 | H8: 不与人次、事件数混用
A9: 已有营收（元） | B9: 1000 | C9: 币种暂按人民币；收入已实现 | D9: 订单、收款、退款、履约与会计口径对账 | E9: 财务运营 | F9: M1 | G9: 用户2026-09-17确认 | H9: 不是利润；待核实净退款口径
A10: 公司主体 | B10: 1 | C10: 已成立公司 | D10: 主体、合同、账户、知识产权归属 | E10: 项目负责人 | F10: M1 | G10: 用户2026-09-17确认 | H10: 不安排重复注册公司
A11: 模型微调 | B11: 已完成 | C11: 处理数据并完成训练微调 | D11: 数据版本、模型版本、基线与测试报告 | E11: 算法负责人 | F11: M1—M3 | G11: 用户2026-09-17确认 | H11: 性能增益数值待补，不预设优于基座
A12: 教学与硬件 | B12: 已有课程库 / 硬件方案 | C12: 仓库记载8模块100知识点；硬件为设计版 | D12: 核对教材质量与最新实物进展 | E12: 教研 / 硬件 | F12: M1 | G12: 课程README / 硬件STATUS | H12: 旧文档不是当前实物验收结论
A13: 收费与公益 | B13: 已有营收 / 半价活动方向 | C13: 延续现有收费与学生优惠安排 | D13: 支付状态、半价规则、受益台账与成本 | E13: 运营负责人 | F13: M1—M2 | G13: 用户原始描述 | H13: 活动的实际人数、次数和成本待补
A15: B｜12个月验收目标（建议值；以质量与可复制为先）
A16: 维度 | B16: 关键成果 | C16: 交付与数量 | D16: 验收口径 | E16: 完成点 | F16: 主责角色 | G16: 任务关联 | H16: 未达标时的动作
A17: 教育教学 | B17: Python教材V1→V2 | C17: 8单元 / 建议32课时；2个综合项目 | D17: 目标—活动—评价全映射；100知识点双人审稿 | E17: M3 / M9 | F17: 教研负责人 | G17: T02—T04、T30 | H17: 删减未审内容，优先可完整授课
A18: 个性化科学性 | B18: 证据驱动的生成闭环 | C18: 诊断→检索→生成→审核→学习→更新 | D18: 抽样100条资源；依据可追溯100%，教师合格率≥90% | E18: M3 | F18: 产品 / 算法 | G18: T05—T06 | H18: 降低自动发布范围，回退到审定资源
A19: 科研可信度 | B19: 可复核的研究结论 | C19: 现有试验回顾1份；新队列验证1轮；报告1份 | D19: 预先确定主指标；效应量+95%区间+缺失/局限 | E19: M7—M8 | F19: 科研负责人 | G19: T07—T13 | H19: 如实报告无效/负向结果，不承诺显著
A20: 模型技术 | B20: 可复现且受控的模型版本 | C20: 已有微调复现；固定独立测试集1套 | D20: 同条件比较基座、RAG、RAG+微调；质量成本一起看 | E20: M3—M6 | F20: 算法负责人 | G20: T08—T09、T11 | H20: 无稳定收益则沿用更便宜的基线
A21: 软硬件结合 | B21: 课堂闭环与教学数据实验 | C21: 1套可用样机→最多10套共享终端 | D21: 72小时连续运行；事件成功率≥99%；比较软硬件增益 | E21: M3—M6 | F21: 硬件 / 后端 | G21: T14—T18 | H21: 无教学或交互收益则保留软件方案
A22: 可落地交付 | B22: 教师可独立使用 | C22: 新环境部署包、教师手册与恢复演练各1套 | D22: 连续4周可用率≥99%；教师独立完成1轮课堂 | E22: M3—M5 | F22: 工程负责人 | G22: T19—T20、T29 | H22: 先修阻断项，再招新班
A23: 商业持续性 | B23: 从首笔验证到可重复付费 | C23: 12个月累计净收款暂定≥1万元；2个机构付费单 | D23: 先统一历史1000元口径；连续3个月经营贡献为正 | E23: M9—M12 | F23: 财务 / 运营 | G23: T21—T24、T27、T31 | H23: 按表04调整价格与成本；不等同净利润
A24: 规模与公益 | B24: 受益可量化、扩展可控制 | C24: 累计≥8班 / ≥300名去重学生；新增≥40半价+20免费名额 | D24: 新增付费与测试分别统计；免费/半价受益不重复计数 | E24: M12 | F24: 教研 / 运营 | G24: T25—T28 | H24: 先核算补贴承受力，再扩大活动
A26: C｜阶段关口：任何规模扩展都以前一阶段验收为条件
A27: 阶段 | B27: 建议窗口 | C27: 必须做成 | D27: 放行条件 | E27: 不做什么 | F27: 负责人 | G27: 对应任务 | H27: 课程交付定位
A28: G1 基线固化 | B28: ="M1｜"&TEXT($B$4,"m/d")&"—"&TEXT(EDATE($B$4,1)-1,"m/d") -> M1｜9/17—10/16 | C28: 归档已有成果；明确课程、数据与收费口径 | D28: 4类已有成果各有负责人和证据入口 | E28: 不重复开展已完成事项 | F28: 项目负责人 | G28: T01、T07、T14、T20、T22 | H28: 先形成可信项目说明
A29: G2 可教学交付 | B29: ="M2—M3｜至"&TEXT(EDATE($B$4,3)-1,"yyyy/m/d") -> M2—M3｜至2026/12/16 | C29: 教材V1、生成链、模型卡、样机与收费审计 | D29: 一节完整课可演示；核心流程无阻断 | E29: 不以界面截图替代课堂闭环 | F29: 教研 / 工程 | G29: T02—T06、T08—T09、T15—T16、T19、T21、T23、T25、T30 | H29: 课程答辩最小完整包；DDL变化只调整此关口
A30: G3 实证与运营 | B30: ="M4—M6｜至"&TEXT(EDATE($B$4,6)-1,"yyyy/m/d") -> M4—M6｜至2027/3/16 | C30: 新队列验证、硬件试点、真实付费与公益台账 | D30: 完成预定干预及数据冻结；订单可逐笔对账 | E30: 不把四班结果外推至所有学生 | F30: 科研 / 运营 | G30: T10—T11、T17—T18、T24、T26、T29 | H30: 补充真实课堂案例
A31: G4 复制与复盘 | B31: ="M7—M12｜至"&TEXT(EDATE($B$4,12)-1,"yyyy/m/d") -> M7—M12｜至2027/9/16 | C31: 报告、第二机构订单、教材V2与年度复盘 | D31: 累计8班300人；正经营贡献；证据包可复核 | E31: 不以亏损补贴长期换人数 | F31: 项目负责人 | G31: T12—T13、T27—T28、T31—T32 | H31: 可复制的课程产品
A32: 24个月方向 | B32: ="M13—M24｜至"&TEXT(EDATE($B$4,24)-1,"yyyy/m/d") -> M13—M24｜至2028/9/16 | C32: 复制到第2门课程；再评估更多学校或硬件量产 | D32: 主课程复购与服务成本稳定后另立预算 | E32: 不预先承诺融资、论文录用或规模营收 | F32: 项目负责人 | G32: T32 | H32: 复用已验证的教材与数据流程
A34: D｜阅读依据：点击来源；具体指标的口径与来源另附于单元格批注
A35: 用户确认 | B35: 已完成基础 | C35: 公司 / 4班约150人 / 微调 / 1000元 | D35: 确认日：2026-09-17 | E35: 本表7—13行 | F35: 规划≠实绩 | G35: 角色待绑定实名 | H35: 项目组补齐原始凭证
A36: 项目材料 | B36: 课程与硬件 | C36: 课程README、个性化实现、硬件STATUS | D36: 见单元格批注的本地路径 | E36: 读取日：2026-09-17 | F36: 以最新实绩更新 | G36: 旧文档不覆盖新确认 | H36: 8模块100知识点按仓库记载
A37: 课程依据 | B37: Python官方教程 | C37: 覆盖校对；本表不照搬教程顺序 | D37: https://docs.python.org/zh-cn/3/tutorial/ | E37: 官方文档 | F37: 用于教材设计 | G37: 详见表02 | H37: 不作为教学效果证明
A38: 教学依据 | B38: Freeman et al. 2014 | C38: 主动练习与即时反馈的设计参考 | D38: https://doi.org/10.1073/pnas.1319030111 | E38: PNAS研究 | F38: 用于教学活动 | G38: 详见表02 | H38: PLEX效果另行实测
A39: 研究依据 | B39: WWC Handbook v5.0 | C39: 基线、流失、班级聚类与研究解释 | D39: https://ies.ed.gov/ncee/wwc/handbooks | E39: 官方研究规范 | F39: 用于研究方案 | G39: 详见表03 | H39: 阈值为本计划建议，非WWC认证
A40: 模型依据 | B40: Model Cards | C40: 模型用途、评测条件与局限记录 | D40: https://research.google/pubs/model-cards-for-model-reporting/ | E40: 研究原文 | F40: 用于模型卡 | G40: 详见表03 | H40: 不等于模型性能已获认证

Sheet 02教材软硬件
A1: PLEX｜教材、个性化与软硬件
A2: 课程范围：零基础大学生 Python 入门；建议8单元×4课时。课时与顺序待任课教师确认，现有100知识点先做映射与质量审核。
A4: A｜8个教材单元：每单元都有可交付作品，而不是只有知识目录
A5: 单元 | B5: 教学主题 | C5: 学生可完成的任务 | D5: 数字教材交付 | E5: 平台中的学习活动 | F5: 硬件 / 数据连接 | G5: 学习评价
A6: U1 | B6: 环境、程序与调试 | C6: 独立运行脚本，解释报错并修复缩进 | D6: 环境指南、示范视频、调试工作纸 | E6: 前测→短示例→代码修改→出口题 | F6: 先用终端事件样例，不要求有设备 | G6: 提交可运行脚本+修错说明
A7: U2 | B7: 变量、类型与输入输出 | C7: 完成类型转换、表达式与输入校验 | D7: 概念卡、正反例、分层练习 | E7: 按类型混淆错误推送补练 | F7: 读取模拟按键数、倒计时数值 | G7: 输入边界用例通过；解释转换原因
A8: U3 | B8: 条件与布尔逻辑 | C8: 编写理解度状态判断规则 | D8: 流程图、分支追踪、错误诊断 | E8: 预测输出→运行→解释差异 | F8: 按“求助/完成/未响应”生成反馈 | G8: 正确处理多条件、边界与异常值
A9: U4 | B9: 循环与基础算法 | C9: 汇总课堂事件，完成计数与搜索 | D9: 循环可视化、追踪表、算法实验 | E9: 补齐循环不变量直觉与终止条件 | F9: 统计终端事件，不访问真实身份 | G9: 测试零条、多条、边界数据
A10: U5 | B10: 字符串与文本处理 | C10: 清洗题目文本、解析简单事件行 | D10: 切片案例、字符串实验、纠错卡 | E10: 同知识点三档任务，逐步撤除提示 | F10: 处理设备匿名事件文本 | G10: 不丢有效字段；能说明清洗规则
A11: U6 | B11: 列表、字典与数据组织 | C11: 用列表/字典组织记录并去重汇总 | D11: 数据结构图、练习集、项目模板 | E11: 比较两种实现并解释选型 | F11: 按匿名会话ID汇总求助事件 | G11: 结果正确，能处理重复与缺失
A12: U7 | B12: 函数、模块与测试 | C12: 把重复逻辑封装为可复用函数 | D12: 函数契约、模块示例、测试清单 | E12: 先补全函数，再独立设计接口 | F12: Python脚本调用测试API或读CSV | G12: 函数职责清晰；正常/异常用例通过
A13: U8 | B13: 文件、异常与综合实践 | C13: 完成学习数据报告与课堂求助助手 | D13: 2个项目说明、评分量规、反思模板 | E13: 项目制：计划→编码→测试→互评 | F13: 用真实脱敏事件与模拟事件分别验证 | G13: 独立迁移任务；代码、报告和反思齐全
A14: 统一单元结构：学习目标→诊断→讲解与正反例→动手练习→形成性评价→错因反馈→迁移任务；评分建议：正确性50%、解释20%、调试20%、反思10%。
A16: B｜个性化生成依据：让每一次推荐都能回答“为什么给这个学生这份资源”
A17: 链路 | B17: 依据 / 输入 | C17: 决策规则 | D17: 产出与留痕 | E17: 质量验收（建议） | F17: 教师 / 学生控制 | G17: 任务关联
A18: P1 诊断 | B18: 前测、近期答题、用时、错因、学习目标 | C18: 以掌握度和先修缺口为主；偏好仅调呈现 | D18: 匿名ID、知识点、事件时间、画像版本 | E18: 缺数据时标注低置信度并追加短测 | F18: 学生可纠正画像；不固定贴“学习风格”标签 | G18: T02、T05
A19: P2 定位 | B19: 先修图谱、薄弱点、复习到期与课时 | C19: 先补前置，再定可完成的小目标 | D19: 目标知识点、先修路径、难度与时长 | E19: 抽样100条均可回溯到学习证据 | F19: 教师可覆盖难度和任务目标 | G19: T05、T06
A20: P3 检索 | B20: 审定教材、题库、代码例题与来源版本 | C20: 限定课程范围，优先检索可引用证据 | D20: document_id、文档版本、片段与检索分数 | E20: 独立检索集覆盖8单元；记录Recall@k | F20: 证据不足改用审定模板或转教师 | G20: T04—T06
A21: P4 生成 | B21: 目标、画像快照、检索片段、约束 | C21: 生成讲解、思维图、练习、拓展阅读或实验 | D21: 资源ID、模型/提示词版本、参数、推荐理由 | E21: 差异应体现在难度、支架和练习；不是只换称呼 | F21: 保留标准教材入口；提供逐级提示 | G21: T05、T09
A22: P5 审核 | B22: 生成资源、引用、答案与运行结果 | C22: 检查事实、先修适配、答案与代码安全 | D22: 自动检查、审核人、通过/退回与原因 | E22: 抽样100条教师合格率≥90%；关键代码全部可运行 | F22: 低置信度和高风险内容必须教师复核 | G22: T04、T06、T19
A23: P6 使用 | B23: 已批准资源与当前教学节奏 | C23: 分块呈现、先作答再反馈、错后提示 | D23: 展示→接受→学习→作答的完整事件链 | E23: 推荐接受率与学习完成率分别统计 | F23: 学生可跳过；核心教材可低带宽访问 | G23: T05、T29
A24: P7 更新 | B24: 退出题、迁移题、复习结果与教师反馈 | C24: 更新掌握度、安排间隔复习，再生成下一步 | D24: 同一trace_id关联画像—资源—评价—新画像 | E24: 评价不重复原题；不将点击或灯色等同掌握 | F24: 确认后的目标不被单次行为静默覆盖 | G24: T05、T11、T12
A26: C｜软硬件与交付：共享课堂终端 + Python数据实践
A27: 工作包 | B27: 场景 / 范围 | C27: 具体实现 | D27: 学生与教师收益 | E27: 验收 / 放行条件 | F27: 成本与限制 | G27: 任务关联
A28: H1 | B28: 实物与必要性核查 | C28: 盘点现有样机、固件和设备API；比较网页按钮 | D28: 明确终端能解决的课堂问题 | E28: M1形成最新状态表、照片与差异清单 | F28: 旧STATUS为设计版；若已有实物则直接补验收 | G28: T14
A29: H2 | B29: 1套端云闭环 | C29: ESP32-S3+屏幕+4按键；匿名会话→事件API→看板 | D29: 任务提醒、理解反馈、求助与教师响应 | E29: 真实设备演示；事件不重计；断网可恢复 | F29: 固件可为C++；Python课通过CSV/API学习，不强行烧录 | G29: T15
A30: H3 | B30: 可靠性与小批量 | C30: 72小时运行；断网、令牌失效、重复上报测试 | D30: 减少课堂中断并保护学习记录 | E30: 事件送达率≥99%；先10人易用性，再最多10套 | F30: 234元/套仅旧BOM估算，另计外壳、维护、检测 | G30: T16—T17
A31: H4 | B31: 教学增益验证 | C31: 相同内容下比较软件入口与硬件入口 | D31: 检验求助响应、注意干扰与参与成本 | E31: 记录求助响应中位数、任务完成率与教师操作时长 | F31: 硬件独立评价；不要把综合干预效果全归因硬件 | G31: T18
A32: D1 | B32: 教师可独立上课 | C32: 课前诊断→发布→课堂干预→课后复习→导出 | D32: 把平台纳入一节完整课与一门完整课 | E32: 1名未参与开发教师按手册独立完成1轮 | F32: 教师端保留审核和覆盖权；培训用时计入成本 | G32: T29—T30
A33: D2 | B33: 教材维护与可访问 | C33: 作者、来源、许可、勘误、版本；字幕与文本替代 | D33: 可持续更新，设备不足仍可完成学习 | E33: 每单元有来源与变更记录；键盘可用、低带宽可读 | F33: AI生成内容经过审核再发布；禁用无授权素材 | G33: T03—T04、T29

Sheet 03科研模型
A1: PLEX｜科研与模型证据闭环
A2: 已有基础：4班约150人测试、数据处理与模型微调已完成。下一步是复核、复现、解释和独立验证；不预设显著提升或论文录用。
A4: A｜研究设计与数据：先分清“已有发现”与“下一轮要验证的假设”
A5: 编号 | B5: 要解决的问题 | C5: 具体做法 | D5: 口径 / 成功条件 | E5: 必须保留的证据 | F5: 结论边界 | G5: 任务关联
A6: R01 | B6: 已有150人的实绩复盘 | C6: 还原4班测试时间、版本、干预方式和对照条件 | D6: 约150人先去重；分别报告参与/有效配对/退出人数 | E6: 匿名名单、原始导出、教师证明、测验版本 | F6: 已完成研究可回顾登记；不得补写为事前预注册 | G6: T01、T07
A7: R02 | B7: 明确教育研究问题 | C7: 主问题：个性化资源是否改善Python迁移能力；次问题：是否节省教师时间 | D7: 主指标只设1项；新一轮可设6周干预+2周延迟测 | E7: 分析方案、课程目标、评分量规、时间表 | F7: 时长为建议；先对齐学期，不承诺正向效果 | G7: T10
A8: R03 | B8: 选择可信对照 | C8: 同内容/时长/教师支持比较常规资源与个性化资源；条件允许再随机分配 | D8: 记录分配层级、基线成绩与教师差异 | E8: 分组日志、实际分配过程、执行偏差 | F8: 只有4班时为探索性；不把150人当150个独立班级 | G8: T10—T11
A9: R04 | B9: 决定样本与新增队列 | C9: 用既有方差、班内相关和最小有意义差异做功效或精度分析 | D9: 300人是运营累计目标；科研样本由设计决定 | E9: 样本量脚本、假设、目标班数和流失预留 | F9: 必要时增加班数；只增每班人数不解决聚类不足 | G9: T10、T28
A10: R05 | B10: 保持评价独立 | C10: 前/后/延迟测用等值题；迁移题不进训练或提示词 | D10: 盲评双人抽评至少20%；报告评分一致性 | E10: 题卷、量规、评分记录、评分分歧处理 | F10: 训练内题成绩只能表示练习表现 | G10: T02、T10—T11
A11: R06 | B11: 数据清洗与授权 | C11: 建匿名ID/班级/版本/资源/结果字典；去重、缺失、异常处理可重跑 | D11: 教学使用、研究与训练用途分别告知和记录授权依据 | E11: 数据字典、清洗脚本、排除日志、用途与保留期记录 | F11: 脱敏不等于匿名化；不上传可识别学生信息给外部模型 | G11: T07、T20
A12: R07 | B12: 报告可复核统计 | C12: 估计基线调整后的组间差异、效应量与95%区间；适配班级分配层级 | D12: 报告主指标、退出/缺失和敏感性分析；副指标注明探索性 | E12: 冻结数据哈希、分析代码、图表与完整报告 | F12: 班级少时区间不稳，强调探索性，不强作因果结论 | G12: T12—T13
A13: R08 | B13: 控制解释范围 | C13: 分别检验学习结果、教师负担、用户体验和硬件价值 | D13: 现有结论逐条关联对应表格或图；无效结果也保留 | E13: 结论—证据映射、反例、版本适用范围 | F13: 满意度/点击率不替代学习增益；整体效果不等于某Agent功劳 | G13: T12—T13、T18
A15: B｜微调完善：用更干净的数据和同条件评测，证明哪些改动值得保留
A16: 编号 | B16: 工作环节 | C16: 具体做法 | D16: 口径 / 放行条件 | E16: 必须保留的证据 | F16: 失效时怎么处理 | G16: 任务关联
A17: M01 | B17: 已有微调可复现 | C17: 登记基座与许可、微调方法、参数量、超参、随机种子和训练环境 | D17: 用同一数据版本复跑；记录差异与算力费用 | E17: 训练配置、日志、数据哈希、权重/适配器、代码提交 | F17: 缺哪项补哪项，不把调用API表述为自研基座 | G17: T09
A18: M02 | B18: 防止测试泄漏 | C18: 核查现有150人数据是否参与训练或调参；按学生/时间/题目近重复隔离 | D18: 训练/验证/测试名单冻结；用过的数据不再冒充独立测试 | E18: 去重报告、分组清单、污染检查与新队列测试集 | F18: 如现有测试已泄漏，重建新学期或新班级测试集 | G18: T08、T10
A19: M03 | B19: 同条件消融比较 | C19: A基座；B基座+RAG；C微调+相同RAG；再按需比较画像/多Agent | D19: 固定题集、生成参数和预算；至少200条覆盖8单元的独立任务 | E19: 模型输出、盲评量规、成本、耗时、失败样本 | F19: 先确认RAG与简单流程价值，再判断微调/多Agent增量 | G19: T06、T09
A20: M04 | B20: 评测教育质量与安全 | C20: 评准确性、引用支持、难度适配、提示质量、代码通过率和泄漏风险 | D20: 建议盲评合格率≥90%；重大事实/隐私错误0；报告样本分母 | E20: 双人复核至少20%；保留分歧、置信区间与失败类别 | F20: 未过门槛的版本不替换线上模型；严重错误先修复 | G20: T06、T09、T19
A21: M05 | B21: 模型上线与回滚 | C21: 模型卡、版本注册、少量灰度、成本告警、教师接管 | D21: 预先冻结主质量指标的最小有意义改进；成本在预算内 | E21: 版本对照、每任务费用、延迟分位数、回滚演练 | F21: 未见可靠增益则保留基线；微调成果可作为负结果报告 | G21: T09、T19
A22: M06 | B22: 数据飞轮可控更新 | C22: 仅用授权且教师复核的困难样本追加训练；每轮保留旧版基准 | D22: 训练集增长有质量记录；独立测试不反复调参消耗 | E22: 样本来源、筛选规则、删除请求记录、版本变更 | F22: 漂移或关键分组性能恶化时暂停更新 | G22: T08—T09、T20
A23: M07 | B23: 科研与产品成果交付 | C23: 1份研究报告/论文初稿；1张模型卡；1套可复现代码与脱敏样例 | D23: 指导教师复核；结果、局限、数据可用性声明齐全 | E23: 报告、模型卡、统计脚本、审阅记录 | F23: 课程结题不以论文录用、专利授权或正结果为前提 | G23: T13、T30
A25: 核心口径：150名学生 ≠ 150条训练样本 ≠ 150次使用；课程效果 ≠ 模型离线得分；微调完成 ≠ 微调有效。每项结论同时注明对象、版本、时间、分母和证据。

Sheet 04商业公益
A1: PLEX｜商业模式与公益测算
A2: 已有营收1000元为用户确认；下方未来12个月全部为情景假设，非实际价格或订单。蓝字黄底可改；公式自动联动。金额均为人民币。
A4: A｜商业闭环：已有公司做规范化经营，先服务好一门课程
A5: 产品 / 付费方 | C5: 交付与收费 | E5: 获客与复购 | G5: 履约与边界
A6: 学生课程包 | C6: 一学期教材+分层练习+限额辅导；基础教材有免费入口 | E6: 教师转介、公开体验课→激活→付费→完成→续购 | G6: 明确期限、额度与退款规则；不付费不影响实验参与及成绩
A7: 机构班级包 | C7: 学校/培训方支付：班级空间、教师看板、资源与服务 | E7: 现有4班案例→教师演示→机构试用→合同→复购 | G7: 按机构包核算席位；同一服务不再向覆盖学生重复收费
A8: 硬件服务 | C8: 先借用/租用共享终端；采购另立报价和交付条件 | E8: 以减少求助等待或课堂操作负担证明价值 | G8: 硬件销售收入不纳入本模型；未验收不计付费产品
A9: 学生半价 / 助学 | C9: 核验学生资格后课程包5折；另设免费助学名额 | E9: 公开规则、名额、期限和受益人数；教师协助触达 | G9: 与研究授权分离；价格让利≠现金捐赠；免费名额不计营收
A11: B｜未来12个月投入与销量假设：三种情景均可编辑，不混入历史收入
A12: 参数 | B12: 保守 | C12: 基准 | D12: 进取 | E12: 单位 | F12: 口径 / 来源
A13: 测算周期 | B13: 12 | C13: 12 | D13: 12 | E13: 月 | F13: 未来12个月；不把全年销量再乘12
A14: 学生课程包原价 | B14: 99 | C14: 99 | D14: 99 | E14: 元/人期 | F14: 规划试价；先做访谈与小额真实付费验证
A15: 学生半价折扣 | B15: 0.5 | C15: 0.5 | D15: 0.5 | E15: 比例 | F15: 按同一服务公示原价5折；不虚构划线价
A16: 全价课程包销量 | B16: 30 | C16: 60 | D16: 100 | E16: 人期 | F16: 与半价销量互斥；销量不等于独立付费人数
A17: 半价课程包销量 | B17: 20 | C17: 40 | D17: 80 | E17: 人期 | F17: 真实付费人期；期内按单去重
A18: 机构包销量 | B18: 1 | C18: 2 | D18: 3 | E18: 单 | F18: 均为未来新增已履约场景假设
A19: 机构包单价 | B19: 1500 | C19: 2000 | D19: 2500 | E19: 元/单 | F19: 独立合同定价假设；尚非签约金额
A20: 每机构包服务席位 | B20: 40 | C20: 40 | D20: 40 | E20: 人期/单 | F20: 机构覆盖者不重复计算为个人付费销量
A21: 预计退款比例 | B21: 0.05 | C21: 0.05 | D21: 0.05 | E21: 比例 | F21: 基于收费总额估计；实际改用订单退款记录
A22: 支付手续费率 | B22: 0.006 | C22: 0.006 | D22: 0.006 | E22: 比例 | F22: 示例费率，待合同替换；按退款前收款计费
A23: 直接服务变动成本 | B23: 12 | C23: 12 | D23: 15 | E23: 元/人期 | F23: 含AI调用/可变运维与履约；所有席位和免费名额均计
A24: 月固定现金成本 | B24: 500 | C24: 500 | D24: 800 | E24: 元/月 | F24: 云资源、基础工具与固定服务费用；团队薪酬见等价工时
... A32: 工时机会成本单价 | B32: 40 | C32: 40 | D32: 40 | E32: 元/小时 | F32: 仅作完整成本估算，非实际工资或现金支付
A33: 历史已实现营收 | B33: ='01目标路线'!B9 -> 1000 | C33: ='01目标路线'!B9 -> 1000 | D33: ='01目标路线'!B9 -> 1000 | E33: 元 | F33: 用户确认1000元；与净收款合计前须统一退款口径
A34: 累计净收款规划目标 | B34: 10000 | C34: 10000 | D34: 10000 | E34: 元 | F34: 本计划建议；用于看差额，不是收入预测保证
A36: C｜自动测算：基准情景若亏损，先优化成本和客单价，不用规模掩盖问题
A37: 指标 | B37: 保守 | C37: 基准 | D37: 进取 | E37: 单位 | F37: 计算口径
A38: 个人付费销量 | B38: =SUM(B16:B17) -> 50 | C38: =SUM(C16:C17) -> 100 | D38: =SUM(D16:D17) -> 180 | E38: 人期 | F38: 全价+半价；独立付费人数须另按用户去重
A39: 全部服务量 | B39: =B38+B18*B20+B30 -> 100 | C39: =C38+C18*C20+C30 -> 200 | D39: =D38+D18*D20+D30 -> 330 | E39: 人期 | F39: 个人+机构席位+免费；三类互斥假设
A40: 个人课程包收款 | B40: =B14*B16+B14*B15*B17 -> 3960 | C40: =C14*C16+C14*C15*C17 -> 7920 | D40: =D14*D16+D14*D15*D17 -> 13860 | E40: 元 | F40: 优惠按实际成交价计入
A41: 机构包收款 | B41: =B18*B19 -> 1500 | C41: =C18*C19 -> 4000 | D41: =D18*D19 -> 7500 | E41: 元 | F41: 机构包销量×单价
A42: 新增收费总额 | B42: =SUM(B40:B41) -> 5460 | C42: =SUM(C40:C41) -> 11920 | D42: =SUM(D40:D41) -> 21360 | E42: 元 | F42: 仅未来新增，不含历史1000元
A43: 预计退款 | B43: =B42*B21 -> 273 | C43: =C42*C21 -> 596 | D43: =D42*D21 -> 1068 | E43: 元 | F43: 交易总额×退款率
A44: 新增净收款 | B44: =B42-B43 -> 5187 | C44: =C42-C43 -> 11324 | D44: =D42-D43 -> 20292 | E44: 元 | F44: 收款减退款；非会计确认营收
A45: 支付手续费 | B45: =B42*B22 -> 32.76 | C45: =C42*C22 -> 71.52 | D45: =D42*D22 -> 128.16 | E45: 元 | F45: 按总收款计费的保守假设
A46: 变动履约成本 | B46: =B39*B23 -> 1200 | C46: =C39*C23 -> 2400 | D46: =D39*D23 -> 4950 | E46: 元 | F46: 包含免费名额成本；退款后服务成本保守保留
A47: 经营贡献 | B47: =B44-B45-B46 -> 3954.24 | C47: =C44-C45-C46 -> 8852.48 | D47: =D44-D45-D46 -> 15213.84 | E47: 元 | F47: 净收款减支付费和直接履约成本
A48: 经营贡献率 | B48: =IFERROR(B47/B44,0) -> 0.76233661 | C48: =IFERROR(C47/C44,0) -> 0.78174497 | D48: =IFERROR(D47/D44,0) -> 0.74974571 | E48: 比例 | F48: 净收款为0时显示—
A49: 固定现金支出 | B49: =B13*B24 -> 6000 | C49: =C13*C24 -> 6000 | D49: =D13*D24 -> 9600 | E49: 元 | F49: 12个月固定成本
A50: 硬件现金投入 | B50: =B25*B26+B27 -> 1000 | C50: =C25*C26+C27 -> 4000 | D50: =D25*D26+D27 -> 5000 | E50: 元 | F50: 新增数量×BOM+追加费用；现金口径一次列入
...

Sheet 05执行证据
A1: PLEX｜执行与证据清单
A2: 32项增量任务；M1从表01启动日算起，日期自动联动。负责人待替换实名；依赖项须在交付验收前完成，可并行准备。状态和证据入口可编辑。
A4: 首周优先：T01固化已有成果、T07整理原始数据、T14核实硬件实况、T20确认数据用途、T22核对公司与账务。以下“待开始”仅指完善任务，不否定已完成成果。
A5: ID | B5: 优先级 | C5: 下一步动作 | D5: 主责角色 | E5: 开始日期 | F5: 截止日期 | G5: 交付依赖 | H5: 交付物 / 验收标准 | I5: 任务状态 | J5: 证据入口（回填）
A6: T01 | B6: P0 | C6: 固化已有成果与最新项目说明 | D6: 项目负责人 | E6: =EDATE('01目标路线'!$B$4,0) -> 46282 | F6: =EDATE('01目标路线'!$B$4,1)-1 -> 46311 | G6: — | H6: 公司、4班约150人、微调、1000元分别有证据索引；更新旧文档 | I6: 待开始 | J6: 待归档
A7: T02 | B7: P0 | C7: 冻结课程目标、8单元矩阵与评分量规 | D7: 教研负责人 | E7: =EDATE('01目标路线'!$B$4,0) -> 46282 | F7: =EDATE('01目标路线'!$B$4,1)-1 -> 46311 | G7: T01 | H7: 100知识点映射到8单元；前后测及2项目量规经教师确认 | I7: 待开始 | J7: 待归档
A8: T03 | B8: P0 | C8: 把课程库编成可授课教材V1 | D8: 教研 / 内容 | E8: =EDATE('01目标路线'!$B$4,1) -> 46312 | F8: =EDATE('01目标路线'!$B$4,2)-1 -> 46342 | G8: T02 | H8: 8单元教材、例题、分层练习、教师教案与勘误入口 | I8: 待开始 | J8: 待归档
A9: T04 | B9: P0 | C9: 审查教材、答案与版权来源 | D9: 教研负责人 | E9: =EDATE('01目标路线'!$B$4,2) -> 46343 | F9: =EDATE('01目标路线'!$B$4,3)-1 -> 46372 | G9: T03 | H9: 100知识点双人审稿；关键示例可运行；素材来源可查 | I9: 待开始 | J9: 待归档
A10: T05 | B10: P0 | C10: 补全个性化依据、追踪与反馈字段 | D10: 产品 / 后端 | E10: =EDATE('01目标路线'!$B$4,1) -> 46312 | F10: =EDATE('01目标路线'!$B$4,2)-1 -> 46342 | G10: T02、T20 | H10: 画像版本—检索引用—生成版本—审核—学习结果能一链追溯 | I10: 待开始 | J10: 待归档
A11: T06 | B11: P0 | C11: 建立真实输出与检索质量评测 | D11: 算法 / 教研 | E11: =EDATE('01目标路线'!$B$4,2) -> 46343 | F11: =EDATE('01目标路线'!$B$4,3)-1 -> 46372 | G11: T04、T05、T08 | H11: 100条资源人工审查；200条独立模型任务；保留失败样例 | I11: 待开始 | J11: 待归档
A12: T07 | B12: P0 | C12: 复盘已完成4班测试并清洗数据 | D12: 科研负责人 | E12: =EDATE('01目标路线'!$B$4,0) -> 46282 | F12: =EDATE('01目标路线'!$B$4,1)-1 -> 46311 | G12: — | H12: 参与/去重/配对/退出人数、字典、清洗脚本与排除日志 | I12: 待开始 | J12: 待归档
A13: T08 | B13: P0 | C13: 核查训练授权和测试泄漏 | D13: 算法 / 科研 | E13: =EDATE('01目标路线'!$B$4,1) -> 46312 | F13: =EDATE('01目标路线'!$B$4,2)-1 -> 46342 | G13: T07、T20 | H13: 学生/时间/近重复题目隔离；训练、验证、测试集版本冻结 | I13: 待开始 | J13: 待归档
A14: T09 | B14: P0 | C14: 复现现有微调并产出模型卡 | D14: 算法负责人 | E14: =EDATE('01目标路线'!$B$4,2) -> 46343 | F14: =EDATE('01目标路线'!$B$4,3)-1 -> 46372 | G14: T08 | H14: 基座/RAG/微调同条件比较；质量、成本、局限和回滚版本齐全 | I14: 待开始 | J14: 待归档
A15: T10 | B15: P1 | C15: 锁定新一轮实验与教师合作 | D15: 科研 / 教研 | E15: =EDATE('01目标路线'!$B$4,3) -> 46373 | F15: =EDATE('01目标路线'!$B$4,4)-1 -> 46403 | G15: T02、T07、T08、T09 | H15: 预先登记主指标、分组、样本量依据、知情流程与时间窗 | I15: 待开始 | J15: 待归档
A16: T11 | B16: P1 | C16: 执行独立新队列教学验证 | D16: 教研 / 科研 | E16: =EDATE('01目标路线'!$B$4,4) -> 46404 | F16: =EDATE('01目标路线'!$B$4,6)-1 -> 46462 | G16: T10、T19 | H16: 按协议完成前测、干预、后测与延迟测；原始数据冻结 | I16: 待开始 | J16: 待归档
A17: T12 | B17: P1 | C17: 形成统计、分组与缺失分析 | D17: 科研负责人 | E17: =EDATE('01目标路线'!$B$4,6) -> 46463 | F17: =EDATE('01目标路线'!$B$4,7)-1 -> 46493 | G17: T11 | H17: 报告基线调整效应、95%区间、退出和敏感性分析 | I17: 待开始 | J17: 待归档
A18: T13 | B18: P1 | C18: 交付科研报告与论文初稿 | D18: 科研负责人 | E18: =EDATE('01目标路线'!$B$4,7) -> 46494 | F18: =EDATE('01目标路线'!$B$4,8)-1 -> 46523 | G18: T12、T18 | H18: 1份可复核报告/初稿；结论对应证据；无效与局限如实呈现 | I18: 待开始 | J18: 待归档
A19: T14 | B19: P0 | C19: 核实硬件进展及课堂必要性 | D19: 硬件 / 教研 | E19: =EDATE('01目标路线'!$B$4,0) -> 46282 | F19: =EDATE('01目标路线'!$B$4,1)-1 -> 46311 | G19: — | H19: 最新实物/固件/API状态表；说明相对网页的预期增益 | I19: 待开始 | J19: 待归档
A20: T15 | B20: P1 | C20: 完成1套真实硬件端云联通 | D20: 硬件 / 后端 | E20: =EDATE('01目标路线'!$B$4,1) -> 46312 | F20: =EDATE('01目标路线'!$B$4,2)-1 -> 46342 | G20: T14、T20 | H20: 按键→事件→教师看板→响应；附设备、固件与演示记录 | I20: 待开始 | J20: 待归档
A21: T16 | B21: P1 | C21: 验收可靠性与小样本易用性 | D21: 测试 / 硬件 | E21: =EDATE('01目标路线'!$B$4,2) -> 46343 | F21: =EDATE('01目标路线'!$B$4,3)-1 -> 46372 | G21: T15 | H21: 72小时、断网/重连/重复上报；10人易用性；失败列表关闭 | I21: 待开始 | J21: 待归档
A22: T17 | B22: P1 | C22: 条件通过后制作最多10套试点终端 | D22: 硬件 / 运营 | E22: =EDATE('01目标路线'!$B$4,3) -> 46373 | F22: =EDATE('01目标路线'!$B$4,5)-1 -> 46434 | G22: T16、T22 | H22: 采购与资产台账、维护手册；真实照片与成本凭证 | I22: 待开始 | J22: 待归档
A23: T18 | B23: P1 | C23: 单独验证硬件的课堂价值 | D23: 教研 / 科研 | E23: =EDATE('01目标路线'!$B$4,5) -> 46435 | F23: =EDATE('01目标路线'!$B$4,6)-1 -> 46462 | G23: T17 | H23: 比较求助响应、课堂操作与干扰；有增益才继续投入 | I23: 待开始 | J23: 待归档
A24: T19 | B24: P0 | C24: 完成正式交付与恢复演练 | D24: 工程负责人 | E24: =EDATE('01目标路线'!$B$4,2) -> 46343 | F24: =EDATE('01目标路线'!$B$4,3)-1 -> 46372 | G24: T05、T09、T20 | H24: 权限、代码执行隔离、备份恢复、失败降级与回滚；4周可用率≥99% | I24: 待开始 | J24: 待归档
A25: T20 | B25: P0 | C25: 确认数据用途、权限与删除流程 | D25: 数据负责人 | E25: =EDATE('01目标路线'!$B$4,0) -> 46282 | F25: =EDATE('01目标路线'!$B$4,1)-1 -> 46311 | G25: — | H25: 用途、授权依据、存储位置、访问人、保留期、退出/删除流程可查 | I25: 待开始 | J25: 待归档
A26: T21 | B26: P0 | C26: 审计现有收费全链路并补齐缺口 | D26: 后端 / 财务 | E26: =EDATE('01目标路线'!$B$4,1) -> 46312 | F26: =EDATE('01目标路线'!$B$4,2)-1 -> 46342 | G26: T01、T22 | H26: 下单、回调验签/幂等、退款、权益回收、对账与票据真实走通 | I26: 待开始 | J26: 待归档
A27: T22 | B27: P0 | C27: 整理公司、合同与财务基础 | D27: 财务 / 项目 | E27: =EDATE('01目标路线'!$B$4,0) -> 46282 | F27: =EDATE('01目标路线'!$B$4,1)-1 -> 46311 | G27: — | H27: 主体与账户、历史1000元对账、教材/代码/数据权属、服务合同归档 | I27: 待开始 | J27: 待归档
A28: T23 | B28: P1 | C28: 校准产品包、定价与服务成本 | D28: 运营 / 财务 | E28: =EDATE('01目标路线'!$B$4,1) -> 46312 | F28: =EDATE('01目标路线'!$B$4,2)-1 -> 46342 | G28: T01、T22 | H28: 访谈至少2名机构决策者和10名学生；更新表04价格/成本假设 | I28: 待开始 | J28: 待归档
A29: T24 | B29: P1 | C29: 跑通稳定付费转化与履约 | D29: 运营负责人 | E29: =EDATE('01目标路线'!$B$4,3) -> 46373 | F29: =EDATE('01目标路线'!$B$4,6)-1 -> 46462 | G29: T04、T19、T21、T23 | H29: 阶段目标：新增1机构单+50个人付费人期；记录渠道、退款与履约 | I29: 待开始 | J29: 待归档
A30: T25 | B30: P1 | C30: 规范半价及免费助学规则 | D30: 运营 / 教研 | E30: =EDATE('01目标路线'!$B$4,1) -> 46312 | F30: =EDATE('01目标路线'!$B$4,2)-1 -> 46342 | G30: T22、T23 | H30: 资格、名额、期限、公示价格、预算及申诉入口；与实验参与分离 | I30: 待开始 | J30: 待归档
A31: T26 | B31: P1 | C31: 形成半年度助学与运营台账 | D31: 运营 / 财务 | E31: =EDATE('01目标路线'!$B$4,5) -> 46435 | F31: =EDATE('01目标路线'!$B$4,6)-1 -> 46462 | G31: T24、T25 | H31: 受益人数去重；列实际收款、让利、免费名额、服务成本和反馈 | I31: 待开始 | J31: 待归档
A32: T27 | B32: P1 | C32: 复制到第二个付费机构 | D32: 运营 / 教研 | E32: =EDATE('01目标路线'!$B$4,8) -> 46524 | F32: =EDATE('01目标路线'!$B$4,9)-1 -> 46554 | G32: T13、T24、T29 | H32: 第二个真实付费机构订单及教师独立使用记录；收款与履约匹配 | I32: 待开始 | J32: 待归档
A33: T28 | B33: P2 | C33: 达成可控扩展并发布教材V2 | D33: 项目 / 教研 | E33: =EDATE('01目标路线'!$B$4,9) -> 46555 | F33: =EDATE('01目标路线'!$B$4,12)-1 -> 46646 | G33: T13、T27 | H33: 累计≥8班≥300去重学生；累计口径对齐后≥1万元；基准助学40半价+20免费 | I33: 待开始 | J33: 待归档
A34: T29 | B34: P1 | C34: 形成教师可独立使用的交付包 | D34: 工程 / 教研 | E34: =EDATE('01目标路线'!$B$4,3) -> 46373 | F34: =EDATE('01目标路线'!$B$4,5)-1 -> 46434 | G34: T04、T19 | H34: 新环境部署、教师手册、培训与支持；非开发教师独立完成1轮 | I34: 待开始 | J34: 待归档
A35: T30 | B35: P0 | C35: 提交课程项目完整成果包 | D35: 项目负责人 | E35: =EDATE('01目标路线'!$B$4,2) -> 46343 | F35: =EDATE('01目标路线'!$B$4,3)-1 -> 46372 | G35: T04、T06、T09、T16、T19、T21 | H35: 教材样章+完整课例+运行演示+已有实证+模型卡+商业/公益台账 | I35: 待开始 | J35: 待归档
A36: T31 | B36: P2 | C36: 年度经营与全成本复盘 | D36: 财务 / 项目 | E36: =EDATE('01目标路线'!$B$4,11) -> 46616 | F36: =EDATE('01目标路线'!$B$4,12)-1 -> 46646 | G36: T26、T27、T28 | H36: 月度收入/退款/成本可对账；连续3月经营贡献为正；如实列完整成本 | I36: 待开始 | J36: 待归档
A37: T32 | B37: P2 | C37: 决定第2课程与下一年度投入 | D37: 项目负责人 | E37: =EDATE('01目标路线'!$B$4,11) -> 46616 | F37: =EDATE('01目标路线'!$B$4,12)-1 -> 46646 | G37: T28、T31 | H37: 仅在复购、教学质量与成本通过评审后立项；形成下一年预算 | I37: 待开始 | J37: 待归档
